Workbook
Name Total_Active: 'Attrition Analysis'!$D$11
Name Total_Employees: 'Attrition Analysis'!$B$11
Name Total_Terminations: 'Attrition Analysis'!$C$11

Sheet Dashboard
A1: Company HR Analytics Dashboard | FY 2010-2023
B4: Total Employees | F4: Active Employees | J4: Terminated | N4: Avg, Attrition Rate
B5: 311 | F5: 207 | J5: 104 | N5: 0.334
A32: Key Findings
A33: Production Department | D33: The production department drives nearly 80% of overall company attrition (80 terminations out of 104 total).
A34: High-Risk Managers | D34: Amy Dunn and Kissy Sullivan run the highest team attrition rate at 62% and 55% respectively. This is nearly double company average. Review is recommended.
A35: …
A36: …
A37: …
A38: …
A39: …

Sheet Raw_data
A1: Employee_Name | B1: EmpID | C1: MarriedID | D1: MaritalStatusID | E1: GenderID | F1: EmpStatusID | G1: DeptID | H1: PerfScoreID | I1: FromDiversityJobFairID | J1: Salary | K1: Termd | L1: PositionID | M1: Position | N1: State | O1: Zip | P1: DOB | Q1: Sex | R1: MaritalDesc | S1: CitizenDesc | T1: HispanicLatino | U1: RaceDesc | V1: DateofHire | W1: DateofTermination | X1: TermReason | Y1: EmploymentStatus | Z1: Department | AA1: ManagerName | AB1: ManagerID | AC1: RecruitmentSource | AD1: PerformanceScore | AE1: EngagementSurvey | AF1: EmpSatisfaction | AG1: SpecialProjectsCount | AH1: LastPerformanceReview_Date | AI1: DaysLateLast30 | AJ1: Absences
A2: Adinolfi, Wilson K | B2: 10026 | C2: 0 | D2: 0 | E2: 1 | F2: 1 | G2: 5 | H2: 4 | I2: 0 | J2: 62506 | K2: 0 | L2: 19 | M2: Production Technician I | N2: MA | O2: 1960 | P2: 30507 | Q2: M | R2: Single | S2: US Citizen | T2: No | U2: White | V2: 40729 | X2: N/A-StillEmployed | Y2: Active | Z2: Production | AA2: Michael Albert | AB2: 22 | AC2: LinkedIn | AD2: Exceeds | AE2: 4.6 | AF2: 5 | AG2: 0 | AH2: 43482 | AI2: 0 | AJ2: 1
A3: Ait Sidi, Karthikeyan | B3: 10084 | C3: 1 | D3: 1 | E3: 1 | F3: 5 | G3: 3 | H3: 3 | I3: 0 | J3: 104437 | K3: 1 | L3: 27 | M3: Sr. DBA | N3: MA | O3: 2148 | P3: 27519 | Q3: M | R3: Married | S3: US Citizen | T3: No | U3: White | V3: 42093 | W3: 42537 | X3: career change | Y3: Voluntarily Terminated | Z3: IT/IS | AA3: Simon Roup | AB3: 4 | AC3: Indeed | AD3: Fully Meets | AE3: 4.96 | AF3: 3 | AG3: 6 | AH3: 42424 | AI3: 0 | AJ3: 17
A4: Akinkuolie, Sarah | B4: 10196 | C4: 1 | D4: 1 | E4: 0 | F4: 5 | G4: 5 | H4: 3 | I4: 0 | J4: 64955 | K4: 1 | L4: 20 | M4: Production Technician II | N4: MA | O4: 1810 | P4: 32405 | Q4: F | R4: Married | S4: US Citizen | T4: No | U4: White | V4: 40729 | W4: 41176 | X4: hours | Y4: Voluntarily Terminated | Z4: Production | AA4: Kissy Sullivan | AB4: 20 | AC4: LinkedIn | AD4: Fully Meets | AE4: 3.02 | AF4: 3 | AG4: 0 | AH4: 41044 | AI4: 0 | AJ4: 3
A5: Alagbe,Trina | B5: 10088 | C5: 1 | D5: 1 | E5: 0 | F5: 1 | G5: 5 | H5: 3 | I5: 0 | J5: 64991 | K5: 0 | L5: 19 | M5: Production Technician I | N5: MA | O5: 1886 | P5: 32413 | Q5: F | R5: Married | S5: US Citizen | T5: No | U5: White | V5: 39454 | X5: N/A-StillEmployed | Y5: Active | Z5: Production | AA5: Elijiah Gray | AB5: 16 | AC5: Indeed | AD5: Fully Meets | AE5: 4.84 | AF5: 5 | AG5: 0 | AH5: 43468 | AI5: 0 | AJ5: 15
A6: Anderson, Carol | B6: 10069 | C6: 0 | D6: 2 | E6: 0 | F6: 5 | G6: 5 | H6: 3 | I6: 0 | J6: 50825 | K6: 1 | L6: 19 | M6: Production Technician I | N6: MA | O6: 2169 | P6: 32759 | Q6: F | R6: Divorced | S6: US Citizen | T6: No | U6: White | V6: 40735 | W6: 42619 | X6: return to school | Y6: Voluntarily Terminated | Z6: Production | AA6: Webster Butler | AB6: 39 | AC6: Google Search | AD6: Fully Meets | AE6: 5 | AF6: 4 | AG6: 0 | AH6: 42401 | AI6: 0 | AJ6: 2
A7: Anderson, Linda | B7: 10002 | C7: 0 | D7: 0 | E7: 0 | F7: 1 | G7: 5 | H7: 4 | I7: 0 | J7: 57568 | K7: 0 | L7: 19 | M7: Production Technician I | N7: MA | O7: 1844 | P7: 28267 | Q7: F | R7: Single | S7: US Citizen | T7: No | U7: White | V7: 40917 | X7: N/A-StillEmployed | Y7: Active | Z7: Production | AA7: Amy Dunn | AB7: 11 | AC7: LinkedIn | AD7: Exceeds | AE7: 5 | AF7: 5 | AG7: 0 | AH7: 43472 | AI7: 0 | AJ7: 15
A8: Andreola, Colby | B8: 10194 | C8: 0 | D8: 0 | E8: 0 | F8: 1 | G8: 4 | H8: 3 | I8: 0 | J8: 95660 | K8: 0 | L8: 24 | M8: Software Engineer | N8: MA | O8: 2110 | P8: 28999 | Q8: F | R8: Single | S8: US Citizen | T8: No | U8: White | V8: 41953 | X8: N/A-StillEmployed | Y8: Active | Z8: Software Engineering | AA8: Alex Sweetwater | AB8: 10 | AC8: LinkedIn | AD8: Fully Meets | AE8: 3.04 | AF8: 3 | AG8: 4 | AH8: 43467 | AI8: 0 | AJ8: 19
A9: Athwal, Sam | B9: 10062 | C9: 0 | D9: 4 | E9: 1 | F9: 1 | G9: 5 | H9: 3 | I9: 0 | J9: 59365 | K9: 0 | L9: 19 | M9: Production Technician I | N9: MA | O9: 2199 | P9: 30365 | Q9: M | R9: Widowed | S9: US Citizen | T9: No | U9: White | V9: 41547 | X9: N/A-StillEmployed | Y9: Active | Z9: Production | AA9: Ketsia Liebig | AB9: 19 | AC9: Employee Referral | AD9: Fully Meets | AE9: 5 | AF9: 4 | AG9: 0 | AH9: 43521 | AI9: 0 | AJ9: 19
A10: Bachiochi, Linda | B10: 10114 | C10: 0 | D10: 0 | E10: 0 | F10: 3 | G10: 5 | H10: 3 | I10: 1 | J10: 47837 | K10: 0 | L10: 19 | M10: Production Technician I | N10: MA | O10: 1902 | P10: 25610 | Q10: F | R10: Single | S10: US Citizen | T10: No | U10: Black or African American | V10: 40000 | X10: N/A-StillEmployed | Y10: Active | Z10: Production | AA10: Brannon Miller | AB10: 12 | AC10: Diversity Job Fair | AD10: Fully Meets | AE10: 4.46 | AF10: 3 | AG10: 0 | AH10: 43490 | AI10: 0 | AJ10: 4
A11: Bacong, Alejandro | B11: 10250 | C11: 0 | D11: 2 | E11: 1 | F11: 1 | G11: 3 | H11: 3 | I11: 0 | J11: 50178 | K11: 0 | L11: 14 | M11: IT Support | N11: MA | O11: 1886 | P11: 32149 | Q11: M | R11: Divorced | S11: US Citizen | T11: No | U11: White | V11: 42009 | X11: N/A-StillEmployed | Y11: Active | Z11: IT/IS | AA11: Peter Monroe | AB11: 7 | AC11: Indeed | AD11: Fully Meets | AE11: 5 | AF11: 5 | AG11: 6 | AH11: 43514 | AI11: 0 | AJ11: 16
A12: Baczenski, Rachael | B12: 10252 | C12: 1 | D12: 1 | E12: 0 | F12: 5 | G12: 5 | H12: 3 | I12: 1 | J12: 54670 | K12: 1 | L12: 19 | M12: Production Technician I | N12: MA | O12: 1902 | P12: 27041 | Q12: F | R12: Married | S12: US Citizen | T12: Yes | U12: Black or African American | V12: 40553 | W12: 42747 | X12: Another position | Y12: Voluntarily Terminated | Z12: Production | AA12: David Stanley | AB12: 14 | AC12: Diversity Job Fair | AD12: Fully Meets | AE12: 4.2 | AF12: 4 | AG12: 0 | AH12: 42399 | AI12: 0 | AJ12: 12
A13: Barbara, Thomas | B13: 10242 | C13: 1 | D13: 1 | E13: 1 | F13: 5 | G13: 5 | H13: 3 | I13: 1 | J13: 47211 | K13: 1 | L13: 19 | M13: Production Technician I | N13: MA | O13: 2062 | P13: 27081 | Q13: M | R13: Married | S13: US Citizen | T13: Yes | U13: Black or African American | V13: 41001 | W13: 42632 | X13: unhappy | Y13: Voluntarily Terminated | Z13: Production | AA13: Kissy Sullivan | AB13: 20 | AC13: Diversity Job Fair | AD13: Fully Meets | AE13: 4.2 | AF13: 3 | AG13: 0 | AH13: 42496 | AI13: 0 | AJ13: 15
A14: Barbossa, Hector | B14: 10012 | C14: 0 | D14: 2 | E14: 1 | F14: 1 | G14: 3 | H14: 4 | I14: 1 | J14: 92328 | K14: 0 | L14: 9 | M14: Data Analyst | N14: TX | O14: 78230 | P14: 32328 | Q14: M | R14: Divorced | S14: US Citizen | T14: No | U14: Black or African American | V14: 41953 | X14: N/A-StillEmployed | Y14: Active | Z14: IT/IS | AA14: Simon Roup | AB14: 4 | AC14: Diversity Job Fair | AD14: Exceeds | AE14: 4.28 | AF14: 4 | AG14: 5 | AH14: 43521 | AI14: 0 | AJ14: 9
A15: Barone, Francesco A | B15: 10265 | C15: 0 | D15: 0 | E15: 1 | F15: 1 | G15: 5 | H15: 3 | I15: 0 | J15: 58709 | K15: 0 | L15: 19 | M15: Production Technician I | N15: MA | O15: 1810 | P15: 30517 | Q15: M | R15: Single | S15: US Citizen | T15: No | U15: Two or more races | V15: 40959 | X15: N/A-StillEmployed | Y15: Active | Z15: Production | AA15: Kelley Spirea | AB15: 18 | AC15: Google Search | AD15: Fully Meets | AE15: 4.6 | AF15: 4 | AG15: 0 | AH15: 43510 | AI15: 0 | AJ15: 7
A16: Barton, Nader | B16: 10066 | C16: 0 | D16: 2 | E16: 1 | F16: 5 | G16: 5 | H16: 3 | I16: 0 | J16: 52505 | K16: 1 | L16: 19 | M16: Production Technician I | N16: MA | O16: 2747 | P16: 28321 | Q16: M | R16: Divorced | S16: US Citizen | T16: No | U16: White | V16: 41176 | W16: 42831 | X16: Another position | Y16: Voluntarily Terminated | Z16: Production | AA16: Michael Albert | AB16: 22 | AC16: On-line Web application | AD16: Fully Meets | AE16: 5 | AF16: 5 | AG16: 0 | AH16: 42796 | AI16: 0 | AJ16: 1
A17: Bates, Norman | B17: 10061 | C17: 0 | D17: 0 | E17: 1 | F17: 4 | G17: 5 | H17: 3 | I17: 0 | J17: 57834 | K17: 1 | L17: 19 | M17: Production Technician I | N17: MA | O17: 2050 | P17: 29877 | Q17: M | R17: Single | S17: US Citizen | T17: No | U17: White | V17: 40595 | W17: 42951 | X17: attendance | Y17: Terminated for Cause | Z17: Production | AA17: Kelley Spirea | AB17: 18 | AC17: Google Search | AD17: Fully Meets | AE17: 5 | AF17: 4 | AG17: 0 | AH17: 42830 | AI17: 0 | AJ17: 20
A18: Beak, Kimberly | B18: 10023 | C18: 1 | D18: 1 | E18: 0 | F18: 2 | G18: 5 | H18: 4 | I18: 0 | J18: 70131 | K18: 0 | L18: 20 | M18: Production Technician II | N18: MA | O18: 2145 | P18: 24214 | Q18: F | R18: Married | S18: US Citizen | T18: No | U18: White | V18: 42572 | X18: N/A-StillEmployed | Y18: Active | Z18: Production | AA18: Kelley Spirea | AB18: 18 | AC18: Employee Referral | AD18: Exceeds | AE18: 4.4 | AF18: 3 | AG18: 0 | AH18: 43479 | AI18: 0 | AJ18: 16
A19: Beatrice, Courtney | B19: 10055 | C19: 0 | D19: 0 | E19: 0 | F19: 1 | G19: 5 | H19: 3 | I19: 0 | J19: 59026 | K19: 0 | L19: 19 | M19: Production Technician I | N19: MA | O19: 1915 | P19: 25868 | Q19: F | R19: Single | S19: Eligible NonCitizen | T19: No | U19: White | V19: 40637 | X19: N/A-StillEmployed | Y19: Active | Z19: Production | AA19: Elijiah Gray | AB19: 16 | AC19: Google Search | AD19: Fully Meets | AE19: 5 | AF19: 5 | AG19: 0 | AH19: 43479 | AI19: 0 | AJ19: 12
A20: Becker, Renee | B20: 10245 | C20: 0 | D20: 0 | E20: 0 | F20: 4 | G20: 3 | H20: 3 | I20: 0 | J20: 110000 | K20: 1 | L20: 8 | M20: Database Administrator | N20: MA | O20: 2026 | P20: 31506 | Q20: F | R20: Single | S20: US Citizen | T20: Yes | U20: White | V20: 41827 | W20: 42259 | X20: performance | Y20: Terminated for Cause | Z20: IT/IS | AA20: Simon Roup | AB20: 4 | AC20: Google Search | AD20: Fully Meets | AE20: 4.5 | AF20: 4 | AG20: 5 | AH20: 42019 | AI20: 0 | AJ20: 8
A21: Becker, Scott | B21: 10277 | C21: 0 | D21: 0 | E21: 1 | F21: 3 | G21: 5 | H21: 3 | I21: 0 | J21: 53250 | K21: 0 | L21: 19 | M21: Production Technician I | N21: MA | O21: 2452 | P21: 28951 | Q21: M | R21: Single | S21: US Citizen | T21: No | U21: Asian | V21: 41463 | X21: N/A-StillEmployed | Y21: Active | Z21: Production | AA21: Webster Butler | AC21: LinkedIn | AD21: Fully Meets | AE21: 4.2 | AF21: 4 | AG21: 0 | AH21: 43476 | AI21: 0 | AJ21: 13
A22: Bernstein, Sean | B22: 10046 | C22: 0 | D22: 0 | E22: 1 | F22: 1 | G22: 5 | H22: 3 | I22: 0 | J22: 51044 | K22: 0 | L22: 19 | M22: Production Technician I | N22: MA | O22: 2072 | P22: 25924 | Q22: M | R22: Single | S22: US Citizen | T22: Yes | U22: White | V22: 41001 | X22: N/A-StillEmployed | Y22: Active | Z22: Production | AA22: Amy Dunn | AB22: 11 | AC22: Google Search | AD22: Fully Meets | AE22: 5 | AF22: 3 | AG22: 0 | AH22: 43479 | AI22: 0 | AJ22: 13
A23: Biden, Lowan M | B23: 10226 | C23: 0 | D23: 2 | E23: 0 | F23: 1 | G23: 5 | H23: 3 | I23: 0 | J23: 64919 | K23: 0 | L23: 19 | M23: Production Technician I | N23: MA | O23: 2027 | P23: 21546 | Q23: F | R23: Divorced | S23: US Citizen | T23: No | U23: Asian | V23: 41505 | X23: N/A-StillEmployed | Y23: Active | Z23: Production | AA23: Ketsia Liebig | AB23: 19 | AC23: Indeed | AD23: Fully Meets | AE23: 4.2 | AF23: 3 | AG23: 0 | AH23: 43475 | AI23: 0 | AJ23: 2
A24: Billis, Helen | B24: 10003 | C24: 1 | D24: 1 | E24: 0 | F24: 1 | G24: 5 | H24: 4 | I24: 0 | J24: 62910 | K24: 0 | L24: 19 | M24: Production Technician I | N24: MA | O24: 2031 | P24: 32752 | Q24: F | R24: Married | S24: US Citizen | T24: No | U24: White | V24: 41827 | X24: N/A-StillEmployed | Y24: Active | Z24: Production | AA24: Brannon Miller | AB24: 12 | AC24: Indeed | AD24: Exceeds | AE24: 5 | AF24: 3 | AG24: 0 | AH24: 43523 | AI24: 0 | AJ24: 19
A25: Blount, Dianna | B25: 10294 | C25: 0 | D25: 0 | E25: 0 | F25: 1 | G25: 5 | H25: 2 | I25: 0 | J25: 66441 | K25: 0 | L25: 20 | M25: Production Technician II | N25: MA | O25: 2171 | P25: 33137 | Q25: F | R25: Single | S25: US Citizen | T25: No | U25: White | V25: 40637 | X25: N/A-StillEmployed | Y25: Active | Z25: Production | AA25: Michael Albert | AB25: 22 | AC25: CareerBuilder | AD25: Needs Improvement | AE25: 2 | AF25: 3 | AG25: 0 | AH25: 43523 | AI25: 2 | AJ25: 3
A26: Bondwell, Betsy | B26: 10267 | C26: 0 | D26: 0 | E26: 0 | F26: 5 | G26: 5 | H26: 3 | I26: 0 | J26: 57815 | K26: 1 | L26: 20 | M26: Production Technician II | N26: MA | O26: 2210 | P26: 24488 | Q26: F | R26: Single | S26: US Citizen | T26: No | U26: White | V26: 40553 | W26: 41733 | X26: career change | Y26: Voluntarily Terminated | Z26: Production | AA26: Elijiah Gray | AB26: 16 | AC26: Google Search | AD26: Fully Meets | AE26: 4.8 | AF26: 5 | AG26: 0 | AH26: 41702 | AI26: 0 | AJ26: 5
A27: Booth, Frank | B27: 10199 | C27: 0 | D27: 0 | E27: 1 | F27: 4 | G27: 3 | H27: 3 | I27: 0 | J27: 103613 | K27: 1 | L27: 30 | M27: Enterprise Architect | N27: CT | O27: 6033 | P27: 23588 | Q27: M | R27: Single | S27: US Citizen | T27: No | U27: Black or African American | V27: 41687 | W27: 42419 | X27: Learned that he is a gangster | Y27: Terminated for Cause | Z27: IT/IS | AA27: Simon Roup | AB27: 4 | AC27: LinkedIn | AD27: Fully Meets | AE27: 3.5 | AF27: 5 | AG27: 7 | AH27: 42379 | AI27: 0 | AJ27: 2
A28: Boutwell, Bonalyn | B28: 10081 | C28: 1 | D28: 1 | E28: 0 | F28: 1 | G28: 1 | H28: 3 | I28: 1 | J28: 106367 | K28: 0 | L28: 26 | M28: Sr. Accountant | N28: MA | O28: 2468 | P28: 31871 | Q28: F | R28: Married | S28: US Citizen | T28: No | U28: Black or African American | V28: 42051 | X28: N/A-StillEmployed | Y28: Active | Z28: Admin Offices | AA28: Brandon R. LeBlanc | AB28: 3 | AC28: Diversity Job Fair | AD28: Fully Meets | AE28: 5 | AF28: 4 | AG28: 3 | AH28: 43514 | AI28: 0 | AJ28: 4
A29: Bozzi, Charles | B29: 10175 | C29: 0 | D29: 0 | E29: 1 | F29: 5 | G29: 5 | H29: 3 | I29: 0 | J29: 74312 | K29: 1 | L29: 18 | M29: Production Manager | N29: MA | O29: 1901 | P29: 25637 | Q29: M | R29: Single | S29: US Citizen | T29: No | U29: Asian | V29: 41547 | W29: 41858 | X29: retiring | Y29: Voluntarily Terminated | Z29: Production | AA29: Janet King | AB29: 2 | AC29: Indeed | AD29: Fully Meets | AE29: 3.39 | AF29: 3 | AG29: 0 | AH29: 41690 | AI29: 0 | AJ29: 14
A30: Brill, Donna | B30: 10177 | C30: 1 | D30: 1 | E30: 0 | F30: 5 | G30: 5 | H30: 3 | I30: 0 | J30: 53492 | K30: 1 | L30: 19 | M30: Production Technician I | N30: MA | O30: 1701 | P30: 33109 | Q30: F | R30: Married | S30: US Citizen | T30: No | U30: White | V30: 41001 | W30: 41440 | X30: Another position | Y30: Voluntarily Terminated | Z30: Production | AA30: David Stanley | AB30: 14 | AC30: Google Search | AD30: Fully Meets | AE30: 3.35 | AF30: 4 | AG30: 0 | AH30: 41337 | AI30: 0 | AJ30: 6
A31: Brown, Mia | B31: 10238 | C31: 1 | D31: 1 | E31: 0 | F31: 1 | G31: 1 | H31: 3 | I31: 1 | J31: 63000 | K31: 0 | L31: 1 | M31: Accountant I | N31: MA | O31: 1450 | P31: 32105 | Q31: F | R31: Married | S31: US Citizen | T31: No | U31: Black or African American | V31: 39748 | X31: N/A-StillEmployed | Y31: Active | Z31: Admin Offices | AA31: Brandon R. LeBlanc | AB31: 1 | AC31: Diversity Job Fair | AD31: Fully Meets | AE31: 4.5 | AF31: 2 | AG31: 6 | AH31: 43480 | AI31: 0 | AJ31: 14
A32: Buccheri, Joseph | B32: 10184 | C32: 0 | D32: 0 | E32: 1 | F32: 1 | G32: 5 | H32: 3 | I32: 0 | J32: 65288 | K32: 0 | L32: 20 | M32: Production Technician II | N32: MA | O32: 1013 | P32: 30525 | Q32: M | R32: Single | S32: US Citizen | T32: No | U32: White | V32: 41911 | X32: N/A-StillEmployed | Y32: Active | Z32: Production | AA32: Webster Butler | AC32: Google Search | AD32: Fully Meets | AE32: 3.19 | AF32: 3 | AG32: 0 | AH32: 43497 | AI32: 0 | AJ32: 9
A33: Bugali, Josephine | B33: 10203 | C33: 0 | D33: 3 | E33: 0 | F33: 3 | G33: 5 | H33: 3 | I33: 1 | J33: 64375 | K33: 0 | L33: 19 | M33: Production Technician I | N33: MA | O33: 2043 | P33: 25506 | Q33: F | R33: Separated | S33: US Citizen | T33: No | U33: Black or African American | V33: 41589 | X33: N/A-StillEmployed | Y33: Active | Z33: Production | AA33: Kissy Sullivan | AB33: 20 | AC33: Diversity Job Fair | AD33: Fully Meets | AE33: 3.5 | AF33: 5 | AG33: 0 | AH33: 43486 | AI33: 0 | AJ33: 17
A34: Bunbury, Jessica | B34: 10188 | C34: 1 | D34: 1 | E34: 0 | F34: 5 | G34: 6 | H34: 3 | I34: 0 | J34: 74326 | K34: 1 | L34: 3 | M34: Area Sales Manager | N34: VA | O34: 21851 | P34: 23529 | Q34: F | R34: Married | S34: Eligible NonCitizen | T34: No | U34: Black or African American | V34: 40770 | W34: 41853 | X34: Another position | Y34: Voluntarily Terminated | Z34: Sales | AA34: John Smith | AB34: 17 | AC34: Google Search | AD34: Fully Meets | AE34: 3.14 | AF34: 5 | AG34: 0 | AH34: 41315 | AI34: 1 | AJ34: 19
A35: Burke, Joelle | B35: 10107 | C35: 0 | D35: 0 | E35: 0 | F35: 1 | G35: 5 | H35: 3 | I35: 0 | J35: 63763 | K35: 0 | L35: 20 | M35: Production Technician II | N35: MA | O35: 2148 | P35: 29282 | Q35: F | R35: Single | S35: US Citizen | T35: No | U35: Black or African American | V35: 40973 | X35: N/A-StillEmployed | Y35: Active | Z35: Production | AA35: Amy Dunn | AB35: 11 | AC35: Employee Referral | AD35: Fully Meets | AE35: 4.51 | AF35: 4 | AG35: 0 | AH35: 43517 | AI35: 0 | AJ35: 3
A36: Burkett, Benjamin | B36: 10181 | C36: 1 | D36: 1 | E36: 1 | F36: 1 | G36: 5 | H36: 3 | I36: 0 | J36: 62162 | K36: 0 | L36: 20 | M36: Production Technician II | N36: MA | O36: 1890 | P36: 28356 | Q36: M | R36: Married | S36: US Citizen | T36: No | U36: White | V36: 40637 | X36: N/A-StillEmployed | Y36: Active | Z36: Production | AA36: Ketsia Liebig | AB36: 19 | AC36: Indeed | AD36: Fully Meets | AE36: 3.25 | AF36: 5 | AG36: 0 | AH36: 43479 | AI36: 0 | AJ36: 15
A37: Cady, Max | B37: 10150 | C37: 0 | D37: 0 | E37: 1 | F37: 1 | G37: 4 | H37: 3 | I37: 0 | J37: 77692 | K37: 0 | L37: 25 | M37: Software Engineering Manager | N37: MA | O37: 2184 | P37: 24433 | Q37: M | R37: Single | S37: US Citizen | T37: No | U37: White | V37: 40770 | X37: N/A-StillEmployed | Y37: Active | Z37: Software Engineering | AA37: Jennifer Zamora | AB37: 5 | AC37: Google Search | AD37: Fully Meets | AE37: 3.84 | AF37: 3 | AG37: 5 | AH37: 43486 | AI37: 0 | AJ37: 4
A38: Candie, Calvin | B38: 10001 | C38: 0 | D38: 0 | E38: 1 | F38: 1 | G38: 5 | H38: 4 | I38: 0 | J38: 72640 | K38: 0 | L38: 18 | M38: Production Manager | N38: MA | O38: 2169 | P38: 30537 | Q38: M | R38: Single | S38: US Citizen | T38: No | U38: White | V38: 42397 | X38: N/A-StillEmployed | Y38: Active | Z38: Production | AA38: Janet King | AB38: 2 | AC38: Indeed | AD38: Exceeds | AE38: 5 | AF38: 3 | AG38: 0 | AH38: 43518 | AI38: 0 | AJ38: 14
A39: Carabbio, Judith | B39: 10085 | C39: 0 | D39: 0 | E39: 0 | F39: 1 | G39: 4 | H39: 3 | I39: 0 | J39: 93396 | K39: 0 | L39: 24 | M39: Software Engineer | N39: MA | O39: 2132 | P39: 31872 | Q39: F | R39: Single | S39: US Citizen | T39: No | U39: White | V39: 41589 | X39: N/A-StillEmployed | Y39: Active | Z39: Software Engineering | AA39: Alex Sweetwater | AB39: 10 | AC39: Indeed | AD39: Fully Meets | AE39: 4.96 | AF39: 4 | AG39: 6 | AH39: 43495 | AI39: 0 | AJ39: 3
A40: Carey, Michael | B40: 10115 | C40: 0 | D40: 0 | E40: 1 | F40: 1 | G40: 5 | H40: 3 | I40: 0 | J40: 52846 | K40: 0 | L40: 19 | M40: Production Technician I | N40: MA | O40: 1701 | P40: 30349 | Q40: M | R40: Single | S40: US Citizen | T40: No | U40: Black or African American | V40: 41729 | X40: N/A-StillEmployed | Y40: Active | Z40: Production | AA40: Kelley Spirea | AB40: 18 | AC40: LinkedIn | AD40: Fully Meets | AE40: 4.43 | AF40: 3 | AG40: 0 | AH40: 43497 | AI40: 0 | AJ40: 14
...

Sheet Data Dictionary
A1: Data Dictionary | B1: https://rpubs.com/rhuebner/hrd_cb_v14
A2: Feature | B2: Description | C2: DataType
A3: Employee Name | B3: Employee’s full name | C3: Text
A4: EmpID | B4: Employee ID is unique to each employee | C4: Text
A5: MarriedID | B5: Is the person married (1 or 0 for yes or no) | C5: Binary
A6: MaritalStatusID | B6: Marital status code that matches the text field MaritalDesc | C6: Integer
A7: EmpStatusID | B7: Employment status code that matches text field EmploymentStatus | C7: Integer
A8: DeptID | B8: Department ID code that matches the department the employee works in | C8: Integer
A9: PerfScoreID | B9: Performance Score code that matches the employee’s most recent performance score | C9: Integer
A10: FromDiversityJobFairID | B10: Was the employee sourced from the Diversity job fair? 1 or 0 for yes or no | C10: Binary
A11: Salary | B11: The person’s yearly salary. $ U.S. Dollars | C11: Float
A12: Termd | B12: Has this employee been terminated - 1 or 0 | C12: Binary
A13: PositionID | B13: An integer indicating the person’s position | C13: Integer
... A37: Absences | B37: The number of times the employee was absent from work. | C37: Integer

Sheet Pivot Tables
A3: Row Labels | B3: Count of EmpID | C3: Sum of Termd | D3: Attr.Total | F3: Row Labels | G3: Count of EmpID | I3: Row Labels | J3: Count of EmpID | K3: Sum of Termd
A4: Production | B4: 209 | C4: 83 | D4: =GETPIVOTDATA("Sum of Termd",$A$3,"Department","Production ")/GETPIVOTDATA("Sum of Termd",$A$3) -> 0.79807692 | F4: N/A-StillEmployed | G4: 207 | I4: Amy Dunn | J4: 21 | K4: 13
A5: IT/IS | B5: 50 | C5: 10 | D5: =GETPIVOTDATA("Sum of Termd",$A$3,"Department","IT/IS")/GETPIVOTDATA("Sum of Termd",$A$3) -> 0.096153846 | F5: Another position | G5: 20 | I5: Webster Butler | J5: 21 | K5: 13
A6: Sales | B6: 31 | C6: 5 | D6: =GETPIVOTDATA("Sum of Termd",$A$3,"Department","Sales")/GETPIVOTDATA("Sum of Termd",$A$3) -> 0.048076923 | F6: unhappy | G6: 14 | I6: Kissy Sullivan | J6: 22 | K6: 12
A7: Software Engineering | B7: 11 | C7: 4 | D7: =GETPIVOTDATA("Sum of Termd",$A$3,"Department","Software Engineering")/GETPIVOTDATA("Sum of Termd",$A$3) -> 0.038461538 | F7: more money | G7: 11 | I7: Michael Albert | J7: 22 | K7: 9
A8: Admin Offices | B8: 9 | C8: 2 | D8: =GETPIVOTDATA("Sum of Termd",$A$3,"Department","Admin Offices")/GETPIVOTDATA("Sum of Termd",$A$3) -> 0.019230769 | F8: career change | G8: 9 | I8: Simon Roup | J8: 17 | K8: 8
A9: Executive Office | B9: 1 | C9: 0 | D9: =GETPIVOTDATA("Sum of Termd",$A$3,"Department","Executive Office")/GETPIVOTDATA("Sum of Termd",$A$3) -> 0 | F9: hours | G9: 8 | I9: Elijiah Gray | J9: 22 | K9: 8
A10: Grand Total | B10: 311 | C10: 104 | F10: attendance | G10: 7 | I10: David Stanley | J10: 21 | K10: 6
F11: relocation out of area | G11: 5 | I11: Kelley Spirea | J11: 22 | K11: 6
F12: return to school | G12: 5 | I12: Brannon Miller | J12: 22 | K12: 6
F13: retiring | G13: 4 | I13: Janet King | J13: 19 | K13: 6
F14: performance | G14: 4 | I14: Ketsia Liebig | J14: 21 | K14: 5
F15: no-call, no-show | G15: 4 | I15: Alex Sweetwater | J15: 9 | K15: 3
F16: military | G16: 4 | I16: John Smith | J16: 14 | K16: 3
F17: maternity leave - did not return | G17: 3 | I17: Brandon R. LeBlanc | J17: 7 | K17: 2
F18: medical issues | G18: 3 | I18: Peter Monroe | J18: 14 | K18: 1
F19: Learned that he is a gangster | G19: 1 | I19: Jennifer Zamora | J19: 7 | K19: 1
F20: Fatal attraction | G20: 1 | I20: Lynn Daneault | J20: 13 | K20: 1
F21: gross misconduct | G21: 1 | I21: Debra Houlihan | J21: 3 | K21: 1
F22: Grand Total | G22: 311 | I22: Brian Champaigne | J22: 8 | K22: 0
I23: Eric Dougall | J23: 4 | K23: 0
I24: Board of Directors | J24: 2 | K24: 0
I25: Grand Total | J25: 311 | K25: 104

Sheet Attrition Analysis
A1: Attrition Analysis -- Who is Leaving and Why?
A3: Attrition by Department | G3: Why Employees Leave | K3: Attrition by Manager (Top 8)
A4: Department | B4: Total Emp | C4: Terminated | D4: Active | E4: Attrition Rate | G4: Reason | H4: Count | I4: % Leave | K4: Manager | L4: Team Size | M4: Team Termd | N4: Attrition Rate
A5: =INDEX('Pivot Tables'!A4,1,1) -> Production | B5: =VLOOKUP(A5,'Pivot Tables'!$A$4:$C$9,2,FALSE) -> 209 | C5: =VLOOKUP(A5,'Pivot Tables'!$A$4:$C$9,3,FALSE) -> 83 | D5: =B5-C5 -> 126 | E5: =C5/B5 -> 0.39712919 | G5: =INDEX('Pivot Tables'!F5:F14,1,1) -> Another position | H5: =VLOOKUP(G5,'Pivot Tables'!F4:G21,2,FALSE) -> 20 | I5: =H5/Total_Terminations -> 0.19230769 | K5: =INDEX('Pivot Tables'!I4:I24,1,1) -> Amy Dunn | L5: =VLOOKUP(K5,'Pivot Tables'!$I$4:$K$24,2,FALSE) -> 21 | M5: =VLOOKUP('Attrition Analysis'!K5,'Pivot Tables'!$I$4:$K$24,3,FALSE) -> 13 | N5: =M5/L5 -> 0.61904762
A6: =INDEX('Pivot Tables'!A7,1,1) -> Software Engineering | B6: =VLOOKUP(A6,'Pivot Tables'!$A$4:$C$9,2,FALSE) -> 11 | C6: =VLOOKUP(A6,'Pivot Tables'!$A$4:$C$9,3,FALSE) -> 4 | D6: =B6-C6 -> 7 | E6: =C6/B6 -> 0.36363636 | G6: =INDEX('Pivot Tables'!F6:F15,1,1) -> unhappy | H6: =VLOOKUP(G6,'Pivot Tables'!F5:G22,2,FALSE) -> 14 | I6: =H6/Total_Terminations -> 0.13461538 | K6: =INDEX('Pivot Tables'!I6:I26,1,1) -> Kissy Sullivan | L6: =VLOOKUP(K6,'Pivot Tables'!$I$4:$K$24,2,FALSE) -> 22 | M6: =VLOOKUP('Attrition Analysis'!K6,'Pivot Tables'!$I$4:$K$24,3,FALSE) -> 12 | N6: =M6/L6 -> 0.54545455
A7: =INDEX('Pivot Tables'!A8,1,1) -> Admin Offices | B7: =VLOOKUP(A7,'Pivot Tables'!$A$4:$C$9,2,FALSE) -> 9 | C7: =VLOOKUP(A7,'Pivot Tables'!$A$4:$C$9,3,FALSE) -> 2 | D7: =B7-C7 -> 7 | E7: =C7/B7 -> 0.22222222 | G7: =INDEX('Pivot Tables'!F7:F16,1,1) -> more money | H7: =VLOOKUP(G7,'Pivot Tables'!F6:G23,2,FALSE) -> 11 | I7: =H7/Total_Terminations -> 0.10576923 | K7: =INDEX('Pivot Tables'!I8:I28,1,1) -> Simon Roup | L7: =VLOOKUP(K7,'Pivot Tables'!$I$4:$K$24,2,FALSE) -> 17 | M7: =VLOOKUP('Attrition Analysis'!K8,'Pivot Tables'!$I$4:$K$24,3,FALSE) -> 9 | N7: =M7/L7 -> 0.52941176
A8: =INDEX('Pivot Tables'!A5,1,1) -> IT/IS | B8: =VLOOKUP(A8,'Pivot Tables'!$A$4:$C$9,2,FALSE) -> 50 | C8: =VLOOKUP(A8,'Pivot Tables'!$A$4:$C$9,3,FALSE) -> 10 | D8: =B8-C8 -> 40 | E8: =C8/B8 -> 0.2 | G8: =INDEX('Pivot Tables'!F8:F17,1,1) -> career change | H8: =VLOOKUP(G8,'Pivot Tables'!F7:G24,2,FALSE) -> 9 | I8: =H8/Total_Terminations -> 0.086538462 | K8: =INDEX('Pivot Tables'!I7:I27,1,1) -> Michael Albert | L8: =VLOOKUP(K8,'Pivot Tables'!$I$4:$K$24,2,FALSE) -> 22 | M8: =VLOOKUP('Attrition Analysis'!K7,'Pivot Tables'!$I$4:$K$24,3,FALSE) -> 8 | N8: =M8/L8 -> 0.36363636
A9: =INDEX('Pivot Tables'!A6,1,1) -> Sales | B9: =VLOOKUP(A9,'Pivot Tables'!$A$4:$C$9,2,FALSE) -> 31 | C9: =VLOOKUP(A9,'Pivot Tables'!$A$4:$C$9,3,FALSE) -> 5 | D9: =B9-C9 -> 26 | E9: =C9/B9 -> 0.16129032 | G9: =INDEX('Pivot Tables'!F9:F18,1,1) -> hours | H9: =VLOOKUP(G9,'Pivot Tables'!F8:G25,2,FALSE) -> 8 | I9: =H9/Total_Terminations -> 0.076923077 | K9: =INDEX('Pivot Tables'!I9:I29,1,1) -> Elijiah Gray | L9: =VLOOKUP(K9,'Pivot Tables'!$I$4:$K$24,2,FALSE) -> 22 | M9: =VLOOKUP('Attrition Analysis'!K9,'Pivot Tables'!$I$4:$K$24,3,FALSE) -> 8 | N9: =M9/L9 -> 0.36363636
A10: =INDEX('Pivot Tables'!A9,1,1) -> Executive Office | B10: =VLOOKUP(A10,'Pivot Tables'!$A$4:$C$9,2,FALSE) -> 1 | C10: =VLOOKUP(A10,'Pivot Tables'!$A$4:$C$9,3,FALSE) -> 0 | D10: =B10-C10 -> 1 | E10: =C10/B10 -> 0 | G10: =INDEX('Pivot Tables'!F10:F19,1,1) -> attendance | H10: =VLOOKUP(G10,'Pivot Tables'!F9:G26,2,FALSE) -> 7 | I10: =H10/Total_Terminations -> 0.067307692 | K10: =INDEX('Pivot Tables'!I13:I33,1,1) -> Janet King | L10: =VLOOKUP(K10,'Pivot Tables'!$I$4:$K$24,2,FALSE) -> 19 | M10: =VLOOKUP('Attrition Analysis'!K13,'Pivot Tables'!$I$4:$K$24,3,FALSE) -> 6 | N10: =M10/L10 -> 0.31578947
A11: Total | B11: =SUM(B5:B10) -> 311 | C11: =SUM(C5:C10) -> 104 | D11: =SUM(D5:D10) -> 207 | G11: =INDEX('Pivot Tables'!F11:F20,1,1) -> relocation out of area | H11: =VLOOKUP(G11,'Pivot Tables'!F10:G27,2,FALSE) -> 5 | I11: =H11/Total_Terminations -> 0.048076923 | K11: =INDEX('Pivot Tables'!I10:I30,1,1) -> David Stanley | L11: =VLOOKUP(K11,'Pivot Tables'!$I$4:$K$24,2,FALSE) -> 21 | M11: =VLOOKUP('Attrition Analysis'!K10,'Pivot Tables'!$I$4:$K$24,3,FALSE) -> 6 | N11: =M11/L11 -> 0.28571429
G12: =INDEX('Pivot Tables'!F12:F21,1,1) -> return to school | H12: =VLOOKUP(G12,'Pivot Tables'!F11:G28,2,FALSE) -> 5 | I12: =H12/Total_Terminations -> 0.048076923 | K12: =INDEX('Pivot Tables'!I11:I31,1,1) -> Kelley Spirea | L12: =VLOOKUP(K12,'Pivot Tables'!$I$4:$K$24,2,FALSE) -> 22 | M12: =VLOOKUP('Attrition Analysis'!K11,'Pivot Tables'!$I$4:$K$24,3,FALSE) -> 6 | N12: =M12/L12 -> 0.27272727
G13: =INDEX('Pivot Tables'!F13:F22,1,1) -> retiring | H13: =VLOOKUP(G13,'Pivot Tables'!F12:G29,2,FALSE) -> 4 | I13: =H13/Total_Terminations -> 0.038461538 | K13: =INDEX('Pivot Tables'!I12:I32,1,1) -> Brannon Miller | L13: =VLOOKUP(K13,'Pivot Tables'!$I$4:$K$24,2,FALSE) -> 22 | M13: =VLOOKUP('Attrition Analysis'!K12,'Pivot Tables'!$I$4:$K$24,3,FALSE) -> 6 | N13: =M13/L13 -> 0.27272727
G14: =INDEX('Pivot Tables'!F14:F23,1,1) -> performance | H14: =VLOOKUP(G14,'Pivot Tables'!F13:G30,2,FALSE) -> 4 | I14: =H14/Total_Terminations -> 0.038461538
